Workbook
Name UPDATE: '[1]Data Sheet'!$E$1

Sheet DCF
B1: | DCF VALUATION OF ASIAN PAINTS LTD.
B5: Calculation of PV of FCFF | G5: 46082 | H5: =G5+366 -> 46448 | I5: =H5+366 -> 46814 | J5: =I5+366 -> 47180 | K5: =J5+366 -> 47546 | L5: =K5+366 -> 47912
B7: EBIT | G7: ='Data Sheet'!L33 -> 6129.51 | H7: =G7*(1+$E$23) -> 7409.8858 | I7: =H7*(1+$E$23) -> 8957.7156 | J7: =I7*(1+$E$23) -> 10828.867 | K7: =J7*(1+$E$23) -> 13090.878 | L7: =K7*(1+$E$23) -> 15825.394
B9: Tax Rate | G9: 0.3 | H9: 0.3 | I9: 0.3 | J9: 0.3 | K9: 0.3 | L9: 0.3
B11: EBIT(1-Tax Rate) | G11: =G7*(1-G9) -> 4290.657 | H11: =H7*(1-H9) -> 5186.92 | I11: =I7*(1-I9) -> 6270.4009 | J11: =J7*(1-J9) -> 7580.207 | K11: =K7*(1-K9) -> 9163.6147 | L11: =L7*(1-L9) -> 11077.776
B13: Less: Reinvestment Rate | G13: ='Intrinsic Growth'!K57 -> 0.47284901 | H13: =G13+(($L$13-$G$13)/4) -> 0.47748676 | I13: =H13+(($L$13-$G$13)/4) -> 0.48212451 | J13: =I13+(($L$13-$G$13)/4) -> 0.48676225 | K13: =J13+(($L$13-$G$13)/4) -> 0.4914 | L13: 0.4914
B15: Free Cash Flow to Firm (FCFF) | G15: =G11*(1-G13) -> 2261.8241 | H15: =H11*(1-H13) -> 2710.2344 | I15: =I11*(1-I13) -> 3247.287 | J15: =J11*(1-J13) -> 3890.4484 | K15: =K11*(1-K13) -> 4660.6144 | L15: =L11*(1-L13) -> 5634.1568
B17: Mid Year Convention | H17: 0.5 | I17: =H17+1 -> 1.5 | J17: =I17+1 -> 2.5 | K17: =J17+1 -> 3.5 | L17: =K17+1 -> 4.5
B18: Discounting Factor | H18: =1/(1+$E$25)^H17 -> 0.93348285 | I18: =1/(1+$E$25)^I17 -> 0.81342782 | J18: =1/(1+$E$25)^J17 -> 0.70881305 | K18: =1/(1+$E$25)^K17 -> 0.61765276 | L18: =1/(1+$E$25)^L17 -> 0.53821658
B20: PV of FCFF | H20: =H15*H18 -> 2529.9573 | I20: =I15*I18 -> 2641.4336 | J20: =J15*J18 -> 2757.6006 | K20: =K15*K18 -> 2878.6414 | L20: =L15*L18 -> 3032.3966
B23: Expected Growth Rate | E23: ='Intrinsic Growth'!K68 -> 0.20888713
B24: Terminal Growth | E24: 0.069
B25: WACC | E25: =WACC!K45 -> 0.14759149
B28: Calculation of Terminal Value
B29: FCFF(n+1) | E29: =L15*(1+E24) -> 6022.9136
B30: WACC | E30: =E25 -> 0.14759149
B31: Terminal Growth Rate | E31: =E24 -> 0.069
B33: Terminal Value | E33: =E29/(E30-E31) -> 76635.702
B36: Calculation of Equity Value per Share
B38: PV of FCFF | E38: =SUM(H20:L20) -> 13840.029
B39: PV of Terminal Value | E39: =E33*L18 -> 41246.606
B40: Enterprise Value | E40: =SUM(E38:E39) -> 55086.635
B42: Add: Cash | E42: ='[2]Data Room'!$N$37 -> 1074
B43: Less: Debt | E43: =SUM('Raw FS'!N9:N10) -> 2293
B44: Value of Equity | E44: =E40+E42-E43 -> 53867.635
B45: No. of Shares | E45: ='Data Sheet'!C6 -> 95.919781
B47: Equity Value per Share | E47: =E44/E45 -> 561.59047
B48: Share Price | E48: 2689
B49: Discount/Premium | E49: =E48/E47 -> 4.7881866

Sheet WACC
B5: Weighted Average Cost of Capital
B7: All figures are in INR, unless stated otherwise
B9: Peer Comps
H10: Debt / | I10: Debt / | J10: Levered | K10: Unlevered
B11: Name of the Comp | D11: Country | E11: Total Debt | F11: Total Equity | G11: Tax Rate 1 | H11: Equity | I11: Capital | J11: Beta 2 | K11: Beta 3
B13: Asian Paints | D13: India | E13: 3928.93 | F13: 255880.39 | G13: 0.3 | H13: =E13/F13 -> 0.015354557 | I13: =E13/(E13+F13) -> 0.01512236 | J13: =Beta!P10 -> 0.91230911 | K13: =J13/1+(1-G13)*H13 -> 0.9230573
B14: Berger Paints | D14: India | E14: 635.13 | F14: 58329.8 | G14: 0.3 | H14: =E14/F14 -> 0.010888602 | I14: =E14/(E14+F14) -> 0.010771318 | J14: 0.671 | K14: =J14/1+(1-G14)*H14 -> 0.67862202
B15: Kansai Nerolac | D15: India | E15: 302.73 | F15: 16326.33 | G15: 0.3 | H15: =E15/F15 -> 0.01854244 | I15: =E15/(E15+F15) -> 0.018204877 | J15: 0.941 | K15: =J15/1+(1-G15)*H15 -> 0.95397971
B16: JSW Dulux | D16: India | E16: 79.1 | F16: 14156.79 | G16: 0.3 | H16: =E16/F16 -> 0.0055874248 | I16: =E16/(E16+F16) -> 0.005556379 | J16: 0.369 | K16: =J16/1+(1-G16)*H16 -> 0.3729112
B17: Indigo Paints | D17: India | E17: 18.37 | F17: 5078.14 | G17: 0.3 | H17: =E17/F17 -> 0.0036174662 | I17: =E17/(E17+F17) -> 0.0036044273 | J17: 1.1 | K17: =J17/1+(1-G17)*H17 -> 1.1025322
B18: Sirca Paints | D18: India | E18: 32.32 | F18: 2232.52 | G18: 0.3 | H18: =E18/F18 -> 0.014476914 | I18: =E18/(E18+F18) -> 0.014270324 | J18: 0.733 | K18: =J18/1+(1-G18)*H18 -> 0.74313384
F21: Average | G21: =AVERAGE(G13:G18) -> 0.3 | H21: =AVERAGE(H13:H18) -> 0.011411234 | I21: =AVERAGE(I13:I18) -> 0.011254948 | J21: =AVERAGE(J13:J18) -> 0.78771818 | K21: =AVERAGE(K13:K18) -> 0.79570605
F22: Median | G22: =MEDIAN(G13:G18) -> 0.3 | H22: =MEDIAN(H13:H18) -> 0.012682758 | I22: =MEDIAN(I13:I18) -> 0.012520821 | J22: =MEDIAN(J13:J18) -> 0.82265455 | K22: =MEDIAN(K13:K18) -> 0.83309557
B25: Cost Of Debt | G25: Cost Of Equity
B27: Pre-Tax Cost Of Debt | E27: 0.0496 | G27: Risk Free Rate | K27: 0.06751
B28: Tax Rate | E28: =G13 -> 0.3 | G28: Equity Risk Premium | K28: =Rm!H9-WACC!K27 -> 0.096982308
B29: Post Tax Cost of Debt | E29: =E27*(1-E28) -> 0.03472 | G29: Levered Beta 4 | K29: =K38 -> 0.84048988
G30: Cost Of Equity | K30: =K27+(K28*K29) -> 0.14902265
B33: Capital Structure | G33: Levered Beta (using comps beta method)
D35: Current | E35: Target | G35: Comps Median Unlevered Beta | K35: =K22 -> 0.83309557
B36: Total Debt | D36: =E13/(E13+F13) -> 0.01512236 | E36: =I22 -> 0.012520821 | G36: Target Debt / Equity | K36: =E40 -> 0.01267958
B37: Market Capitalization | D37: =F13/(F13+E13) -> 0.98487764 | E37: =E38-E36 -> 0.98747918 | G37: Tax Rate | K37: =G18 -> 0.3
B38: Total Capital | D38: =SUM(D36:D37) -> 1 | E38: 1 | G38: Levered Beta | K38: =K35*(1+(1-K37)*K36) -> 0.84048988
B40: Debt / Equity | D40: =D36/D37 -> 0.015354557 | E40: =E36/E37 -> 0.01267958 | G40: Weighted Average Cost of Capital
J42: Total Cost | K42: Total Weight
B43: Notes: | G43: Debt | J43: =E29 -> 0.03472 | K43: =E36 -> 0.012520821
B44: 1. Tax Rate is considered as Marginal Tax Rate for the country | G44: Equity | J44: =K30 -> 0.14902265 | K44: =E37 -> 0.98747918
B45: 2. Levered Beta is based on 5 year monthly data | G45: Weighted Average Cost of Capital | K45: =(J43*K43)+(J44*K44) -> 0.14759149
B46: 3. Unlevered Beta = Levered Beta/(1+(1-Tax Rate)*Debt/Equity
B47: 4. Levered Beta = Unlevered Beta*(1+(1-Tax Rate)*Debt/Equity

Sheet Beta
B5: Regression Beta - 2 Years Weekly
B8: Asian Paints Weekly Returns | G8: Nifty Weekly Returns | K8: Beta Drifting | O8: Beta 1 | P8: =SLOPE(D12:D115, I12:I115) -> 0.91230911
O9: Beta 2 | P9: =_xlfn.COVARIANCE.S(D12:D115,I12:I115)/_xlfn.VAR.S(I12:I115) -> 0.91230911
B10: Date | C10: Adj Close | D10: Weekly Returns | G10: Date | H10: Adj Close | I10: Weekly Returns | K10: Leveraged Beta | M10: =P10 -> 0.91230911 | O10: Beta 3 | P10: =P29 -> 0.91230911
B11: 45383 | C11: 2796.21 | G11: 45383 | H11: 22513.7 | K11: Leveraged Beta Weight | M11: 0.75
B12: 45390 | C12: 2768.13 | D12: =(C12-C11)/C12 -> -0.010144032 | G12: 45390 | H12: 22519.4 | I12: =(H12-H11)/H11 -> 0.00025317918 | O12: SUMMARY OUTPUT
B13: 45397 | C13: 2723.57 | D13: =(C13-C12)/C13 -> -0.016360879 | G13: 45397 | H13: 22147 | I13: =(H13-H12)/H12 -> -0.016536853 | K13: Market Beta | M13: 1
B14: 45404 | C14: 2758.1 | D14: =(C14-C13)/C14 -> 0.012519488 | G14: 45404 | H14: 22419.95 | I14: =(H14-H13)/H13 -> 0.012324468 | K14: Market Beta Weight | M14: 0.25 | O14: Regression Statistics
B15: 45411 | C15: 2841.11 | D15: =(C15-C14)/C15 -> 0.029217454 | G15: 45411 | H15: 22475.85 | I15: =(H15-H14)/H14 -> 0.0024933151 | O15: Multiple R | P15: 0.49118859
B16: 45418 | C16: 2687.4 | D16: =(C16-C15)/C16 -> -0.057196547 | G16: 45418 | H16: 22055.2 | I16: =(H16-H15)/H15 -> -0.018715644 | K16: Adjusted Beta | M16: =(M10*M11) + (M13*M14) -> 0.93423183 | O16: R Square | P16: 0.24126623
B17: 45425 | C17: 2731.14 | D17: =(C17-C16)/C17 -> 0.01601529 | G17: 45425 | H17: 22466.1 | I17: =(H17-H16)/H16 -> 0.018630527 | O17: Adjusted R Square | P17: 0.23382766
B18: 45432 | C18: 2787.77 | D18: =(C18-C17)/C18 -> 0.020313727 | G18: 45432 | H18: 22957.1 | I18: =(H18-H17)/H17 -> 0.021855151 | O18: Standard Error | P18: 0.029491354
B19: 45439 | C19: 2794.03 | D19: =(C19-C18)/C19 -> 0.0022404913 | G19: 45439 | H19: 22530.7 | I19: =(H19-H18)/H18 -> -0.018573775 | O19: Observations | P19: 104
B20: 45446 | C20: 2839.12 | D20: =(C20-C19)/C20 -> 0.015881682 | G20: 45446 | H20: 23290.15 | I20: =(H20-H19)/H19 -> 0.033707342
B21: 45453 | C21: 2860.62 | D21: =(C21-C20)/C21 -> 0.0075158532 | G21: 45453 | H21: 23465.6 | I21: =(H21-H20)/H20 -> 0.0075332276 | O21: ANOVA
B22: 45460 | C22: 2830.51 | D22: =(C22-C21)/C22 -> -0.010637659 | G22: 45460 | H22: 23501.1 | I22: =(H22-H21)/H21 -> 0.0015128529 | P22: df | Q22: SS | R22: MS | S22: F | T22: Significance F
B23: 45467 | C23: 2856.16 | D23: =(C23-C22)/C23 -> 0.0089805893 | G23: 45467 | H23: 24010.6 | I23: =(H23-H22)/H22 -> 0.021679836 | O23: Regression | P23: 1 | Q23: 0.028209586 | R23: 0.028209586 | S23: 32.434507 | T23: 1.1956639e-07
B24: 45474 | C24: 2874.62 | D24: =(C24-C23)/C24 -> 0.0064217183 | G24: 45474 | H24: 24323.85 | I24: =(H24-H23)/H23 -> 0.013046321 | O24: Residual | P24: 102 | Q24: 0.088713475 | R24: 0.00086973995
B25: 45481 | C25: 2936.55 | D25: =(C25-C24)/C25 -> 0.021089374 | G25: 45481 | H25: 24502.15 | I25: =(H25-H24)/H24 -> 0.0073302541 | O25: Total | P25: 103 | Q25: 0.11692306
B26: 45488 | C26: 2884.56 | D26: =(C26-C25)/C26 -> -0.018023546 | G26: 45488 | H26: 24530.9 | I26: =(H26-H25)/H25 -> 0.0011733664
B27: 45495 | C27: 2888.57 | D27: =(C27-C26)/C27 -> 0.0013882302 | G27: 45495 | H27: 24834.85 | I27: =(H27-H26)/H26 -> 0.012390495 | P27: Coefficients | Q27: Standard Error | R27: t Stat | S27: P-value | T27: Lower 95% | U27: Upper 95% | V27: Lower 95.0% | W27: Upper 95.0%
B28: 45502 | C28: 3041.85 | D28: =(C28-C27)/C28 -> 0.050390387 | G28: 45502 | H28: 24717.7 | I28: =(H28-H27)/H27 -> -0.0047171616 | O28: Intercept | P28: -0.0031738465 | Q28: 0.0028918975 | R28: -1.0974962 | S28: 0.27500867 | T28: -0.0089099114 | U28: 0.0025622184 | V28: -0.0089099114 | W28: 0.0025622184
B29: 45509 | C29: 2977.13 | D29: =(C29-C28)/C29 -> -0.021739057 | G29: 45509 | H29: 24367.5 | I29: =(H29-H28)/H28 -> -0.014167985 | O29: X Variable 1 | P29: 0.91230911 | Q29: 0.16019109 | R29: 5.6951301 | S29: 1.1956639e-07 | T29: 0.59457084 | U29: 1.2300474 | V29: 0.59457084 | W29: 1.2300474
B30: 45516 | C30: 2984.52 | D30: =(C30-C29)/C30 -> 0.0024761101 | G30: 45516 | H30: 24541.15 | I30: =(H30-H29)/H29 -> 0.0071262953
B31: 45523 | C31: 3088.8 | D31: =(C31-C30)/C31 -> 0.033760684 | G31: 45523 | H31: 24823.15 | I31: =(H31-H30)/H30 -> 0.011490904
B32: 45530 | C32: 3061.53 | D32: =(C32-C31)/C32 -> -0.0089073111 | G32: 45530 | H32: 25235.9 | I32: =(H32-H31)/H31 -> 0.016627624
B33: 45537 | C33: 3205.37 | D33: =(C33-C32)/C33 -> 0.044874695 | G33: 45537 | H33: 24852.15 | I33: =(H33-H32)/H32 -> -0.015206511
B34: 45544 | C34: 3287.96 | D34: =(C34-C33)/C34 -> 0.025118919 | G34: 45544 | H34: 25356.5 | I34: =(H34-H33)/H33 -> 0.020294019
B35: 45551 | C35: 3237.92 | D35: =(C35-C34)/C35 -> -0.015454366 | G35: 45551 | H35: 25790.95 | I35: =(H35-H34)/H34 -> 0.017133674
B36: 45558 | C36: 3241.64 | D36: =(C36-C35)/C36 -> 0.0011475673 | G36: 45558 | H36: 26178.95 | I36: =(H36-H35)/H35 -> 0.015044037
B37: 45565 | C37: 3008.37 | D37: =(C37-C36)/C37 -> -0.077540329 | G37: 45565 | H37: 25014.6 | I37: =(H37-H36)/H36 -> -0.044476574
B38: 45572 | C38: 2973.8 | D38: =(C38-C37)/C38 -> -0.011624857 | G38: 45572 | H38: 24964.25 | I38: =(H38-H37)/H37 -> -0.0020128245
B39: 45579 | C39: 2929.69 | D39: =(C39-C38)/C39 -> -0.0150562 | G39: 45579 | H39: 24854.05 | I39: =(H39-H38)/H38 -> -0.0044143125
B40: 45586 | C40: 2896.26 | D40: =(C40-C39)/C40 -> -0.011542472 | G40: 45586 | H40: 24180.8 | I40: =(H40-H39)/H39 -> -0.027088141
B41: 45593 | C41: 2878.48 | D41: =(C41-C40)/C41 -> -0.0061768711 | G41: 45593 | H41: 24304.35 | I41: =(H41-H40)/H40 -> 0.0051094257
... B115: 46111 | C115: 2146.58 | D115: =(C115-C114)/C115 -> -0.019486812 | G115: 46111 | H115: 22331.4 | I115: =(H115-H114)/H114 -> -0.021393889

Sheet Rm
B5: Nifty Market Returns
B7: Year | C7: Annual | F7: Average Return | H7: =AVERAGE(C8:C33) -> 0.15149231
B8: 2000 | C8: -0.1465 | F8: Dividend Yield | H8: 0.013
B9: 2001 | C9: -0.1618 | F9: Total Market Return | H9: =SUM(H7:H8) -> 0.16449231
B10: 2002 | C10: 0.0325
B11: 2003 | C11: 0.719
B12: 2004 | C12: 0.1068
B13: 2005 | C13: 0.3634
B14: 2006 | C14: 0.3983
B15: 2007 | C15: 0.5477
B16: 2008 | C16: -0.5179
B17: 2009 | C17: 0.7576
B18: 2010 | C18: 0.1795
B19: 2011 | C19: -0.2462
B20: 2012 | C20: 0.277
B21: 2013 | C21: 0.0676
... B33: 2025 | C33: 0.1051

Sheet Intrinsic Growth
B5: Calcuation of ROIC | G5: 44621 | H5: 44986 | I5: 45352 | J5: 45717 | K5: 46082
B6: Current Assets
B7: Inventories | G7: 6153 | H7: 6211 | I7: 5923 | J7: 6719 | K7: 5744
B8: Trade receivables + | G8: 3871 | H8: 4637 | I8: 4889 | J8: 4314 | K8: 4462
B9: Loans n Advances | G9: 8 | H9: 12 | I9: 17 | J9: 22 | K9: 27
B10: Other asset items | G10: 2869 | H10: 3024 | I10: 3555 | J10: 3319 | K10: 4662
B11: Total Current Assets | G11: =SUM(G7:G10) -> 12901 | H11: =SUM(H7:H10) -> 13884 | I11: =SUM(I7:I10) -> 14384 | J11: =SUM(J7:J10) -> 14374 | K11: =SUM(K7:K10) -> 14895
B14: Current Liabilities
B15: Trade Payables | G15: 4164 | H15: 3635 | I15: 3831 | J15: 3848 | K15: 3863
B16: Advance from Customers | G16: 76 | H16: 108 | I16: 154 | J16: 174 | K16: 107
B17: Other liability items | G17: 2932 | H17: 3657 | I17: 4017 | J17: 3984 | K17: 4604
B18: Total Current Liabilities | G18: =SUM(G15:G17) -> 7172 | H18: =SUM(H15:H17) -> 7400 | I18: =SUM(I15:I17) -> 8002 | J18: =SUM(J15:J17) -> 8006 | K18: =SUM(K15:K17) -> 8574
A20: # | B20: Net Working Capital | G20: =G11-G18 -> 5729 | H20: =H11-H18 -> 6484 | I20: =I11-I18 -> 6382 | J20: =J11-J18 -> 6368 | K20: =K11-K18 -> 6321
B23: Non Current Assets
B24: Land | G24: 644 | H24: 804 | I24: 1126 | J24: 1035 | K24: 1204
B25: Building | G25: 2325 | H25: 2883 | I25: 3390 | J25: 3771 | K25: 4124
B26: Plant Machinery | G26: 4531 | H26: 4825 | I26: 5422 | J26: 7576 | K26: 8210
B27: Equipments | G27: 253 | H27: 270 | I27: 298 | J27: 325 | K27: 351
B28: Furniture n fittings | G28: 113 | H28: 146 | I28: 175 | J28: 203 | K28: 216
B29: Vehicles | G29: 32 | H29: 36 | I29: 40 | J29: 34 | K29: 45
B30: Intangible Assets | G30: 345 | H30: 422 | I30: 850 | J30: 827 | K30: 833
B31: Other fixed assets | G31: 294 | H31: 289 | I31: 321 | J31: 328 | K31: 335
B32: Gross Block | G32: =SUM(G24:G31) -> 8537 | H32: =SUM(H24:H31) -> 9675 | I32: =SUM(I24:I31) -> 11622 | J32: =SUM(J24:J31) -> 14099 | K32: =SUM(K24:K31) -> 15318
B33: Accumulated Depreciation | G33: -3019 | H33: -3905 | I33: -4475 | J33: -4879 | K33: -5676
B34: Net Current Assets | G34: =SUM(G32:G33) -> 5518 | H34: =SUM(H32:H33) -> 5770 | I34: =SUM(I32:I33) -> 7147 | J34: =SUM(J32:J33) -> 9220 | K34: =SUM(K32:K33) -> 9642
A37: # | B37: Invested Capital | G37: =G20+G34 -> 11247 | H37: =H20+H34 -> 12254 | I37: =I20+I34 -> 13529 | J37: =J20+J34 -> 15588 | K37: =K20+K34 -> 15963
B38: EBIT | G38: ='Data Sheet'!H33 -> 4228.89 | H38: ='Data Sheet'!I33 -> 5744.4 | I38: ='Data Sheet'!J33 -> 7455.48 | J38: ='Data Sheet'!K33 -> 5287.61 | K38: ='Data Sheet'!L33 -> 6129.51
A40: # | B40: ROIC | G40: =G38/G37 -> 0.3760016 | H40: =H38/H37 -> 0.46877754 | I40: =I38/I37 -> 0.55107399 | J40: =J38/J37 -> 0.33921029 | K40: =K38/K37 -> 0.38398233
B44: Calculation of Reinvestment Rate | G44: 44621 | H44: 44986 | I44: 45352 | J44: 45717 | K44: 46082
B46: Net CapEx | G46: =-SUM('Raw FS'!J56:J57) -> 511 | H46: =-SUM('Raw FS'!K56:K57) -> 1420 | I46: =-SUM('Raw FS'!L56:L57) -> 2491 | J46: =-SUM('Raw FS'!M56:M57) -> 1820 | K46: =-SUM('Raw FS'!N56:N57) -> 1484
B47: Change in Working Capital | H47: =H20-G20 -> 755 | I47: =I20-H20 -> -102 | J47: =J20-I20 -> -14 | K47: =K20-J20 -> -47
B49: EBIT | G49: =G38 -> 4228.89 | H49: =H38 -> 5744.4 | I49: =I38 -> 7455.48 | J49: =J38 -> 5287.61 | K49: =K38 -> 6129.51
B50: Marginal Tax Rate | G50: 0.3 | H50: 0.3 | I50: 0.3 | J50: 0.3 | K50: 0.3
B51: EBIT(1-Tax Rate) | G51: =G49*(1-G50) -> 2960.223 | H51: =H49*(1-H50) -> 4021.08 | I51: =I49*(1-I50) -> 5218.836 | J51: =J49*(1-J50) -> 3701.327 | K51: =K49*(1-K50) -> 4290.657
B53: Reinvestment | H53: =SUM(H46:H47) -> 2175 | I53: =SUM(I46:I47) -> 2389 | J53: =SUM(J46:J47) -> 1806 | K53: =SUM(K46:K47) -> 1437
A54: # | B54: Reinvestment Rate | H54: =H53/H51 -> 0.54089946 | I54: =I53/I51 -> 0.45776491 | J54: =J53/J51 -> 0.48793311 | K54: =K53/K51 -> 0.33491374
I56: 4 year Average | K56: =AVERAGE(H54:K54) -> 0.45537781
I57: 4 year Median | K57: =MEDIAN(H54:K54) -> 0.47284901
B60: Calculation of Growth Rate | G60: 44621 | H60: 44986 | I60: 45352 | J60: 45717 | K60: 46082
B62: Reinvestment Rate | H62: =H54 -> 0.54089946 | I62: =I54 -> 0.45776491 | J62: =J54 -> 0.48793311 | K62: =K54 -> 0.33491374
...

Sheet Raw FS
B5: Particulars | C5: 42064 | D5: 42430 | E5: 42795 | F5: 43160 | G5: 43525 | H5: 43891 | I5: 44256 | J5: 44621 | K5: 44986 | L5: 45352 | M5: 45717 | N5: 46082
B6: Equity Capital | C6: 96 | D6: 96 | E6: 96 | F6: 96 | G6: 96 | H6: 96 | I6: 96 | J6: 96 | K6: 96 | L6: 96 | M6: 96 | N6: 96
B7: Reserves | C7: 4646 | D7: 6429 | E7: 7508 | F7: 8314 | G7: 9375 | H7: 10034 | I7: 12710 | J7: 13716 | K7: 15896 | L7: 18632 | M7: 19304 | N7: 21276
B8: Borrowings
B9: Long term Borrowings | C9: 78 | D9: 73 | E9: 41 | F9: 28 | G9: 19 | H9: 19 | I9: 15 | J9: 45 | K9: 76 | L9: 54 | M9: 260 | N9: 1247
B10: Short term Borrowings | C10: 332 | D10: 231 | E10: 504 | F10: 492 | G10: 597 | H10: 321 | I10: 334 | J10: 731 | K10: 896 | L10: 1053 | M10: 604 | N10: 1046
B11: Lease Liabilities | C11: 0 | D11: 0 | E11: 0 | F11: 0 | G11: 693 | H11: 764 | I11: 745 | J11: 811 | K11: 960 | L11: 1367 | M11: 1427 | N11: 1636
B12: Other Borrowings | C12: 8 | D12: 20 | E12: 15 | F12: 13 | G12: 11 | H12: 15 | I12: 0 | J12: 0 | K12: 0 | L12: 0 | M12: 0 | N12: 0
B13: Other Liabilities
B14: Non controlling int | C14: 264 | D14: 384 | E14: 375 | F14: 328 | G14: 361 | H14: 404 | I14: 423 | J14: 388 | K14: 454 | L14: 695 | M14: 659 | N14: 643
B15: Trade Payables | C15: 1549 | D15: 1565 | E15: 1923 | F15: 2160 | G15: 2394 | H15: 2137 | I15: 3379 | J15: 4164 | K15: 3635 | L15: 3831 | M15: 3848 | N15: 3863
B16: Advance from Customers | C16: 5 | D16: 12 | E16: 17 | F16: 16 | G16: 13 | H16: 29 | I16: 41 | J16: 76 | K16: 108 | L16: 154 | M16: 174 | N16: 107
B17: Other liability items | C17: 1937 | D17: 1750 | E17: 1925 | F17: 2316 | G17: 2690 | H17: 2320 | I17: 2613 | J17: 2932 | K17: 3657 | L17: 4017 | M17: 3984 | N17: 4604
B18: Total Liabilities | C18: 8914 | D18: 10559 | E18: 12405 | F18: 13763 | G18: 16249 | H18: 16138 | I18: 20355 | J18: 22958 | K18: 25779 | L18: 29901 | M18: 30355 | N18: 34519
B20: Fixed Assets
B21: Land | C21: 251 | D21: 429 | E21: 408 | F21: 586 | G21: 605 | H21: 640 | I21: 644 | J21: 644 | K21: 804 | L21: 1126 | M21: 1035 | N21: 1204
B22: Building | C22: 962 | D22: 923 | E22: 931 | F22: 957 | G22: 2402 | H22: 2257 | I22: 2249 | J22: 2325 | K22: 2883 | L22: 3390 | M22: 3771 | N22: 4124
B23: Plant Machinery | C23: 2132 | D23: 1793 | E23: 1980 | F23: 2157 | G23: 4006 | H23: 4208 | I23: 4340 | J23: 4531 | K23: 4825 | L23: 5422 | M23: 7576 | N23: 8210
B24: Equipments | C24: 171 | D24: 97 | E24: 119 | F24: 200 | G24: 221 | H24: 241 | I24: 243 | J24: 253 | K24: 270 | L24: 298 | M24: 325 | N24: 351
B25: Furniture n fittings | C25: 83 | D25: 49 | E25: 59 | F25: 72 | G25: 88 | H25: 94 | I25: 99 | J25: 113 | K25: 146 | L25: 175 | M25: 203 | N25: 216
B26: Vehicles | C26: 18 | D26: 11 | E26: 14 | F26: 27 | G26: 47 | H26: 43 | I26: 38 | J26: 32 | K26: 36 | L26: 40 | M26: 34 | N26: 45
B27: Intangible Assets | C27: 351 | D27: 339 | E27: 276 | F27: 468 | G27: 512 | H27: 505 | I27: 476 | J27: 345 | K27: 422 | L27: 850 | M27: 827 | N27: 833
B28: Other fixed assets | C28: 145 | D28: 103 | E28: 128 | F28: 238 | G28: 261 | H28: 293 | I28: 302 | J28: 294 | K28: 289 | L28: 321 | M28: 328 | N28: 335
B29: Gross Block | C29: 4112 | D29: 3744 | E29: 3914 | F29: 4705 | G29: 8141 | H29: 8282 | I29: 8392 | J29: 8538 | K29: 9676 | L29: 11622 | M29: 14099 | N29: 15316
B30: Accumulated Depreciation | C30: -1452 | D30: -327 | E30: -610 | F30: -973 | G30: -1644 | H30: -2010 | I30: -2533 | J30: -3019 | K30: -3905 | L30: -4475 | M30: -4879 | N30: -5676
B31: Net Block | C31: =SUM(C29:C30) -> 2660 | D31: =SUM(D29:D30) -> 3417 | E31: =SUM(E29:E30) -> 3304 | F31: =SUM(F29:F30) -> 3732 | G31: =SUM(G29:G30) -> 6497 | H31: =SUM(H29:H30) -> 6272 | I31: =SUM(I29:I30) -> 5859 | J31: =SUM(J29:J30) -> 5519 | ... N31: =SUM(N29:N30) -> 9640
B33: CWIP | C33: 196 | D33: 107 | E33: 258 | F33: 1405 | G33: 210 | H33: 140 | I33: 183 | J33: 426 | K33: 1020 | L33: 2698 | M33: 1254 | N33: 1849
B34: Investments | C34: 1588 | D34: 2712 | E34: 2652 | F34: 2141 | G34: 2569 | H34: 2019 | I34: 4737 | J34: 3248 | K34: 4262 | L34: 4588 | M34: 4725 | N34: 7062
B36: Other Assets
B37: Inventories | C37: 2259 | D37: 1998 | E37: 2627 | F37: 2658 | G37: 3150 | H37: 3390 | I37: 3799 | J37: 6153 | K37: 6211 | L37: 5923 | M37: 6719 | N37: 5744
B38: Trade receivables + | C38: 1182 | D38: 1187 | E38: 1447 | F38: 1731 | G38: 1907 | H38: 1795 | I38: 2602 | J38: 3871 | K38: 4637 | L38: 4889 | M38: 4314 | N38: 4462
B39: Cash Equivalents | C39: 204 | D39: 424 | E39: 801 | F39: 405 | G39: 445 | H39: 783 | I39: 611 | J39: 864 | K39: 844 | L39: 1084 | M39: 782 | N39: 1074
B40: Loans n Advances | C40: 8 | D40: 9 | E40: 14 | F40: 13 | G40: 16 | H40: 12 | I40: 11 | J40: 8 | K40: 12 | L40: 17 | M40: 22 | N40: 27
B41: Other asset items | C41: 817 | D41: 705 | E41: 1303 | F41: 1678 | G41: 1456 | H41: 1727 | I41: 2555 | J41: 2869 | K41: 3024 | L41: 3555 | M41: 3319 | N41: 4662
B42: Total Assets | C42: 8914 | D42: 10559 | E42: 12405 | F42: 13763 | G42: 16249 | H42: 16138 | I42: 20355 | J42: 22958 | K42: 25779 | L42: 29901 | M42: 30355 | N42: 34519
B46: Particulars | C46: 42064 | D46: 42430 | E46: 42795 | F46: 43160 | G46: 43525 | H46: 43891 | I46: 44256 | J46: 44621 | K46: 44986 | L46: 45352 | M46: 45717 | N46: 46082
B47: Cash from Operating Activity - | C47: 1188 | D47: 2243 | E47: 1527 | F47: 2113 | G47: 2470 | H47: 3038 | I47: 3683 | J47: 986 | K47: 4193 | L47: 6104 | M47: 4424 | N47: 7088
B48: Profit from operations | C48: 2271 | D48: 2848 | E48: 3056 | F48: 3274 | G48: 3861 | H48: 4380 | I48: 4970 | J48: 4957 | K48: 6460 | L48: 7929 | M48: 6390 | N48: 7186
B49: Receivables | C49: -155 | D49: -146 | E49: -475 | F49: -483 | G49: -205 | H49: 160 | I49: -849 | J49: -1326 | K49: -834 | L49: -362 | M49: 282 | N49: -274
B50: Inventory | C50: -144 | D50: 202 | E50: -629 | F50: -39 | G50: -492 | H50: -251 | I50: -409 | J50: -2354 | K50: -56 | L50: 315 | M50: -805 | N50: 976
...

Sheet Data Sheet
B1: COMPANY NAME | C1: ASIAN PAINTS LTD | F1: =IF(C2<>C3, "A NEW VERSION OF THE WORKSHEET IS AVAILABLE", "")
B2: LATEST VERSION | C2: 2.1 | F2: PLEASE DO NOT MAKE ANY CHANGES TO THIS SHEET
B3: CURRENT VERSION | C3: 2.1
B5: META
B6: Number of shares | C6: =IF(C9>0, C9/C8, 0) -> 95.919781
B7: Face Value | C7: 1
B8: Current Price | C8: 2689
B9: Market Capitalization | C9: 257928.29
B15: PROFIT & LOSS
B16: Report Date | C16: 42825 | D16: 43190 | E16: 43555 | F16: 43921 | G16: 44286 | H16: 44651 | I16: 45016 | J16: 45382 | K16: 45747 | L16: 46112
B17: Sales | C17: 15061.99 | D17: 16824.55 | E17: 19240.13 | F17: 20211.25 | G17: 21712.79 | H17: 29101.28 | I17: 34488.59 | J17: 35494.73 | K17: 33905.62 | L17: 35583.54
B18: Raw Material Cost | C18: 7452.6 | D18: 8128.17 | E18: 9974.4 | F18: 9981.99 | G18: 10425.55 | H18: 17123.25 | I18: 18985.53 | J18: 17410.84 | K18: 17504.51 | L18: 17142.01
B19: Change in Inventory | C19: 528.6 | D19: -142.13 | E19: 293.26 | F19: 239.15 | G19: 92.45 | H19: 1324.97 | I19: 309.73 | J19: -363.8 | K19: 205 | L19: -603.68
B20: Power and Fuel | C20: 106.02 | D20: 110.3 | E20: 119.63 | F20: 97.79 | G20: 86.05 | H20: 117.23 | I20: 138.29 | J20: 133.25 | K20: 148.58 | L20: 167.1
B21: Other Mfr. Exp | C21: 1662.75 | D21: 1691.68 | E21: 1862.35 | F21: 1946.12 | G21: 2068.31 | H21: 2880.45 | I21: 2916.2 | J21: 2767.18 | K21: 2687.4 | L21: 2767.11
B22: Employee Cost | C22: 1039.89 | D22: 1121.89 | E22: 1242.69 | F22: 1371.27 | G22: 1547.61 | H22: 1794.61 | I22: 2036.41 | J22: 2334.92 | K22: 2605.78 | L22: 2809.73
B23: Selling and admin | C23: 4364.04 | D23: 2254.92 | E23: 2366.87 | F23: 2311.51 | G23: 2245.69 | H23: 2941.98 | I23: 3500.84 | J23: 3811.86 | K23: 3874.94 | L23: 4112.07
B24: Other Expenses | C24: -2028.47 | D24: 171.45 | E24: 202.51 | F24: 579.95 | G24: 576.43 | H24: 765.12 | I24: 961.21 | J24: 1087.9 | K24: 1283.2 | L24: 1282.11
B25: Other Income | C25: 337.9 | D25: 336.41 | E25: 273.77 | F25: 350.1 | G25: 331.65 | H25: 295.88 | I25: 431.46 | J25: 820.96 | K25: 350.22 | L25: 727.97
B26: Depreciation | C26: 334.79 | D26: 360.47 | E26: 622.14 | F26: 780.5 | G26: 791.27 | H26: 816.36 | I26: 858.02 | J26: 853 | K26: 1026.34 | L26: 1228.85
B27: Interest | C27: 37.33 | D27: 41.47 | E27: 110.47 | F27: 102.33 | G27: 91.63 | H27: 95.41 | I27: 144.45 | J27: 205.17 | K27: 227.02 | L27: 195.41
... B31: Dividend Amount | C31: 987.98 | D31: 834.5 | E31: 1007.16 | F31: 1151.04 | G31: 1712.17 | H31: 1836.87 | I31: 2460.35 | J31: 3194.14 | K31: 2378.82 | L31: 2637.8
B33: EBIT | C33: =C30+C29+C27 -> 2920.05 | D33: =D30+D29+D27 -> 3121.36 | E33: =E30+E29+E27 -> 3364.45 | F33: =F30+F29+F27 -> 3662.35 | G33: =G30+G29+G27 -> 4328.52 | H33: =H30+H29+H27 -> 4228.89 | I33: =I30+I29+I27 -> 5744.4 | J33: =J30+J29+J27 -> 7455.48 | ... L33: =L30+L29+L27 -> 6129.51
B40: Quarters
B41: Report Date | C41: 45291 | D41: 45382 | E41: 45473 | F41: 45565 | G41: 45657 | H41: 45747 | I41: 45838 | J41: 45930 | K41: 46022 | L41: 46112
B42: Sales | C42: 9103.09 | D42: 8730.76 | E42: 8969.73 | F42: 8027.54 | G42: 8549.44 | H42: 8358.91 | I42: 8938.55 | J42: 8531.27 | K42: 8867.02 | L42: 9246.7
B43: Expenses | C43: 7047 | D43: 7039.39 | E43: 7275.96 | F43: 6788.03 | G43: 6912.71 | H43: 6922.71 | I43: 7313.58 | J43: 7027.89 | K43: 7086.06 | L43: 7460.09
B44: Other Income | C44: 186.46 | D44: 212.43 | E44: 192.93 | F44: 24.53 | G44: 192.82 | H44: -60.06 | I44: 229.11 | J44: 236.94 | K44: 69.14 | L44: 196.59
B45: Depreciation | C45: 220.35 | D45: 225.61 | E45: 227.7 | F45: 241.99 | G45: 255.55 | H45: 301.1 | I45: 300.87 | J45: 304.93 | K45: 313.07 | L45: 309.98
B46: Interest | C46: 54.42 | D46: 54.1 | E46: 55.38 | F46: 63.01 | G46: 55.84 | H46: 52.79 | I46: 44.5 | J46: 43.87 | K46: 47.94 | L46: 59.1
B47: Profit before tax | C47: 1967.78 | D47: 1624.09 | E47: 1603.62 | F47: 959.04 | G47: 1518.16 | H47: 1022.25 | I47: 1508.71 | J47: 1391.52 | K47: 1489.09 | L47: 1614.12
B48: Tax | C48: 492.62 | D48: 348.79 | E48: 416.83 | F48: 265.38 | G48: 389.73 | H48: 321.42 | I48: 391.66 | J48: 373.29 | K48: 415.17 | L48: 428.63
B49: Net profit | C49: 1447.72 | D49: 1256.72 | E49: 1169.98 | F49: 694.64 | G49: 1110.48 | H49: 692.13 | I49: 1099.77 | J49: 993.59 | K49: 1059.87 | L49: 1172.12
B50: Operating Profit | C50: 2056.09 | D50: 1691.37 | E50: 1693.77 | F50: 1239.51 | G50: 1636.73 | H50: 1436.2 | I50: 1624.97 | J50: 1503.38 | K50: 1780.96 | L50: 1786.61
B55: BALANCE SHEET
B56: Report Date | C56: 42825 | D56: 43190 | E56: 43555 | F56: 43921 | G56: 44286 | H56: 44651 | I56: 45016 | J56: 45382 | K56: 45747 | L56: 46112
B57: Equity Share Capital | C57: 95.92 | D57: 95.92 | E57: 95.92 | F57: 95.92 | G57: 95.92 | H57: 95.92 | I57: 95.92 | J57: 95.92 | K57: 95.92 | L57: 95.92
B58: Reserves | C58: 7507.97 | D58: 8314.31 | E58: 9374.63 | F58: 10034.24 | G58: 12710.37 | H58: 13715.64 | I58: 15896.31 | J58: 18632.38 | K58: 19303.89 | L58: 21275.67
B59: Borrowings | C59: 560.34 | D59: 533.43 | E59: 1319.6 | F59: 1118.5 | G59: 1093.12 | H59: 1586.88 | I59: 1932.62 | J59: 2474.38 | K59: 2290.29 | L59: 3928.93
B60: Other Liabilities | C60: 4240.96 | D60: 4819.82 | E60: 5458.69 | F60: 4889.31 | G60: 6455.93 | H60: 7559.99 | I60: 7854.48 | J60: 8698.09 | K60: 8665.15 | L60: 9218.23
...

Sheet DATA
B3: Asian Paints Data | F3: Nifty Data | J3: Nifty Yearly returns
B5: Date | C5: Adj Close | F5: Date | G5: Adj Close | J5: Year | K5: Annual
B6: 45383 | C6: 2796.21 | F6: 45383 | G6: 22513.7 | J6: 2000 | K6: -0.1465
B7: 45390 | C7: 2768.13 | F7: 45390 | G7: 22519.4 | J7: 2001 | K7: -0.1618
B8: 45397 | C8: 2723.57 | F8: 45397 | G8: 22147 | J8: 2002 | K8: 0.0325
B9: 45404 | C9: 2758.1 | F9: 45404 | G9: 22419.95 | J9: 2003 | K9: 0.719
B10: 45411 | C10: 2841.11 | F10: 45411 | G10: 22475.85 | J10: 2004 | K10: 0.1068
B11: 45418 | C11: 2687.4 | F11: 45418 | G11: 22055.2 | J11: 2005 | K11: 0.3634
B12: 45425 | C12: 2731.14 | F12: 45425 | G12: 22466.1 | J12: 2006 | K12: 0.3983
B13: 45432 | C13: 2787.77 | F13: 45432 | G13: 22957.1 | J13: 2007 | K13: 0.5477
B14: 45439 | C14: 2794.03 | F14: 45439 | G14: 22530.7 | J14: 2008 | K14: -0.5179
B15: 45446 | C15: 2839.12 | F15: 45446 | G15: 23290.15 | J15: 2009 | K15: 0.7576
B16: 45453 | C16: 2860.62 | F16: 45453 | G16: 23465.6 | J16: 2010 | K16: 0.1795
B17: 45460 | C17: 2830.51 | F17: 45460 | G17: 23501.1 | J17: 2011 | K17: -0.2462
... B31: 45558 | C31: 3241.64 | F31: 45558 | G31: 26178.95 | J31: 2025 | K31: 0.1051
B32: 45565 | C32: 3008.37 | F32: 45565 | G32: 25014.6
B33: 45572 | C33: 2973.8 | F33: 45572 | G33: 24964.25
B34: 45579 | C34: 2929.69 | F34: 45579 | G34: 24854.05
B35: 45586 | C35: 2896.26 | F35: 45586 | G35: 24180.8
B36: 45593 | C36: 2878.48 | F36: 45593 | G36: 24304.35
B37: 45600 | C37: 2711.64 | F37: 45600 | G37: 24148.2
B38: 45607 | C38: 2431.32 | F38: 45607 | G38: 23532.7
B39: 45614 | C39: 2424.75 | F39: 45614 | G39: 23907.25
B40: 45621 | C40: 2432 | F40: 45621 | G40: 24131.1
B41: 45628 | C41: 2383.06 | F41: 45628 | G41: 24677.8
B42: 45635 | C42: 2361.43 | F42: 45635 | G42: 24768.3
B43: 45642 | C43: 2238.54 | F43: 45642 | G43: 23587.5
... B110: 46111 | C110: 2146.58 | F110: 46111 | G110: 22331.4
